Workbook

Sheet information
B2: Nanopore barcoding (ITS5-ITS4)
B4: Forward primer: ITS5 (GGAAGTAAAAGTCGTAACAAGG)
B5: Reverse primer: ITS4 (TCCTCCGCTTATTGATATGC)
B6: Sample index length: 9 bp | Combinatorial indexing max. 40 x 36 primers → max. 15 plates
B7: These primers are suitable for most fungi
B10: PCR | F10: Example PCR mix using GoTaq G2 Master Mix
B11: Make sure to record the primer plate/DNA plate | F11: Reactions | G11: original conc. | H11: target conc. | I11: one reaction | J11: =ROUND(4*96*1.15,0) -> 442 | K11: 4 plates: 442 rxn | M11: Cycling | N11: Temperature | O11: Time
B12: combinations that you used. | F12: Master Mix | G12: 2 | H12: 1 | I12: =H12/G12*I$16 -> 5 | J12: =J$11*I12 -> 2210 | K12: = 4 x 96 + 15% | M12: Initial denat. | N12: 95 °C | O12: 2 min
B13: Never use the same primer plate twice within the | F13: Primer mix | G13: 5 | H13: 0.5 | I13: =2*H13/G13*I$16 -> 2 | M13: Denaturation | N13: 95 °C | O13: 30 s
B14: same Nanopore run. | F14: DNA | I14: 1 | K14: pre-dilute if necessary | M14: Annealing | N14: 52 °C | O14: 30 s
B15: Consider adding PCR negative controls, as they will | F15: water | I15: =I16-SUM(I12:I14) -> 2 | J15: =J$11*I15 -> 884 | M15: Extension | N15: 72 °C | O15: 75 s
B16: help to identify PCR contamination. | F16: total | I16: 10 | J16: =J$11*I16 -> 4420 | M16: Final extension | N16: 72 °C | O16: 5 min
M17: ~36 cycles (do enough cycles, at least part of samples should reach stationary phase of PCR)
B18: Proceed with pooling, library preparation and sequencing according to separate instructions (…) | M18: The final concentration should be somehow similar across a Nanopore run
B21: Prepare this metadata sheet
A23: 2) | B23: Add the sample names: | D23: - insert in the plates sheet if your samples are in the plate layout
D24: (samples are automatically found in the sample_list sheet)
D25: - insert in the sample_list sheet (sample column) if your sample names are associated
D26: with a well coordinate (use VLOOKUP if not in order)
A28: 3) | B28: Complete sample_list: | D28: taxon may contain taxonomic names (known or putative species name, Genus sp., etc.)
B29: (optional) | D29: (e.g. join on sample name with VLOOKUP)
D30: These will be compared to automatic sequence-based taxonomy assignments, to recognize contamination
D31: and/or highlight other problems (wrong identification, preparation errors)
D33: 'known sequence' may contain already known sequences (e.g. from Sanger sequencing)
D34: These will be compared to the Nanopore sequences
D36: 'sample type' can be helpful to distinguish control samples (positive or negative)
D37: from “real” samples
D38: This will show up in the final Excel report and in diagnostic plots
A40: 4) | B40: Place a copy of this Excel file as meta.xlsx in the run directory
B42: If pooling several primer combinations (different loci) in the same Nanopore run,
B43: prepare the Excel metadata sheets separately for each amplicon, then combine
B44: the content of both the sample_list and primers workbooks in a final meta.xlsx
B45: sheet (copy by value).
B46: Unused barcode combinations (empty sample column) are not strictly needed in sample_list.
B49: Run the analysis
B51: For details see:
B52: https://github.com/markschl/DadaNanoBC

Sheet plates
C1: Paste sample names for the corresponding DNA plates → they will appear in "sample_list"
P2: rows: barcoded forward primers (ITS5)
C3: bc019 | D3: bc062 | E3: bc065 | F3: bc082 | G3: bc120 | H3: bc139 | I3: bc145 | J3: bc150 | K3: bc183 | L3: bc218 | M3: bc219 | N3: bc245 | P3: columns: barcoded reverse primers (ITS4)
A4: Plate | B4: 1 | C4: 1 | D4: 2 | E4: 3 | F4: 4 | G4: 5 | H4: 6 | I4: 7 | J4: 8 | K4: 9 | L4: 10 | M4: 11 | N4: 12
A5: bc018 | B5: A
A6: bc060 | B6: B
A7: bc061 | B7: C
A8: bc062 | B8: D
A9: bc095 | B9: E
A10: bc139 | B10: F
A11: bc148 | B11: G
A12: bc157 | B12: H
A14: Plate | B14: 2 | C14: 1 | D14: 2 | E14: 3 | F14: 4 | G14: 5 | H14: 6 | I14: 7 | J14: 8 | K14: 9 | L14: 10 | M14: 11 | N14: 12
A15: bc168 | B15: A
A16: bc183 | B16: B
A17: bc192 | B17: C
A18: bc205 | B18: D
A19: bc219 | B19: E
A20: bc220 | B20: F
A21: bc258 | B21: G
A22: bc264 | B22: H
A24: Plate | B24: 3 | C24: 1 | D24: 2 | E24: 3 | F24: 4 | G24: 5 | H24: 6 | I24: 7 | J24: 8 | K24: 9 | L24: 10 | M24: 11 | N24: 12
A25: bc272 | B25: A
A26: bc277 | B26: B
A27: bc282 | B27: C
A28: bc286 | B28: D
A29: bc298 | B29: E
A30: bc314 | B30: F
A31: bc321 | B31: G
A32: bc324 | B32: H
A34: Plate | B34: 4 | C34: 1 | D34: 2 | E34: 3 | F34: 4 | G34: 5 | H34: 6 | I34: 7 | J34: 8 | K34: 9 | L34: 10 | M34: 11 | N34: 12
A35: bc327 | B35: A
A36: bc357 | B36: B
A37: bc361 | B37: C
A38: bc362 | B38: D
A39: bc368 | B39: E
A40: bc370 | B40: F
A41: bc377 | B41: G
A42: bc406 | B42: H
A44: Plate | B44: 5 | C44: 1 | D44: 2 | E44: 3 | F44: 4 | G44: 5 | H44: 6 | I44: 7 | J44: 8 | K44: 9 | L44: 10 | M44: 11 | N44: 12
...

Sheet sample_list
A1: plate | B1: well | C1: amplicon | D1: indexes | E1: sample | F1: sample type | G1: taxon | H1: known sequence
A2: 1 | B2: A01 | C2: ITS5-ITS4 | D2: =OFFSET(plates!$B$4,CODE(LEFT(B2,1))-64,-1)&"-"&OFFSET(plates!$B$4,-1,MID(B2,2,3)+0) -> bc018-bc019 | E2: =OFFSET(plates!$B$4,CODE(LEFT(B2,1))-64,MID(B2,2,3)+0)&""
A3: 1 | B3: B01 | C3: ITS5-ITS4 | D3: =OFFSET(plates!$B$4,CODE(LEFT(B3,1))-64,-1)&"-"&OFFSET(plates!$B$4,-1,MID(B3,2,3)+0) -> bc060-bc019 | E3: =OFFSET(plates!$B$4,CODE(LEFT(B3,1))-64,MID(B3,2,3)+0)&""
A4: 1 | B4: C01 | C4: ITS5-ITS4 | D4: =OFFSET(plates!$B$4,CODE(LEFT(B4,1))-64,-1)&"-"&OFFSET(plates!$B$4,-1,MID(B4,2,3)+0) -> bc061-bc019 | E4: =OFFSET(plates!$B$4,CODE(LEFT(B4,1))-64,MID(B4,2,3)+0)&""
A5: 1 | B5: D01 | C5: ITS5-ITS4 | D5: =OFFSET(plates!$B$4,CODE(LEFT(B5,1))-64,-1)&"-"&OFFSET(plates!$B$4,-1,MID(B5,2,3)+0) -> bc062-bc019 | E5: =OFFSET(plates!$B$4,CODE(LEFT(B5,1))-64,MID(B5,2,3)+0)&""
A6: 1 | B6: E01 | C6: ITS5-ITS4 | D6: =OFFSET(plates!$B$4,CODE(LEFT(B6,1))-64,-1)&"-"&OFFSET(plates!$B$4,-1,MID(B6,2,3)+0) -> bc095-bc019 | E6: =OFFSET(plates!$B$4,CODE(LEFT(B6,1))-64,MID(B6,2,3)+0)&""
A7: 1 | B7: F01 | C7: ITS5-ITS4 | D7: =OFFSET(plates!$B$4,CODE(LEFT(B7,1))-64,-1)&"-"&OFFSET(plates!$B$4,-1,MID(B7,2,3)+0) -> bc139-bc019 | E7: =OFFSET(plates!$B$4,CODE(LEFT(B7,1))-64,MID(B7,2,3)+0)&""
A8: 1 | B8: G01 | C8: ITS5-ITS4 | D8: =OFFSET(plates!$B$4,CODE(LEFT(B8,1))-64,-1)&"-"&OFFSET(plates!$B$4,-1,MID(B8,2,3)+0) -> bc148-bc019 | E8: =OFFSET(plates!$B$4,CODE(LEFT(B8,1))-64,MID(B8,2,3)+0)&""
A9: 1 | B9: H01 | C9: ITS5-ITS4 | D9: =OFFSET(plates!$B$4,CODE(LEFT(B9,1))-64,-1)&"-"&OFFSET(plates!$B$4,-1,MID(B9,2,3)+0) -> bc157-bc019 | E9: =OFFSET(plates!$B$4,CODE(LEFT(B9,1))-64,MID(B9,2,3)+0)&""
A10: 1 | B10: A02 | C10: ITS5-ITS4 | D10: =OFFSET(plates!$B$4,CODE(LEFT(B10,1))-64,-1)&"-"&OFFSET(plates!$B$4,-1,MID(B10,2,3)+0) -> bc018-bc062 | E10: =OFFSET(plates!$B$4,CODE(LEFT(B10,1))-64,MID(B10,2,3)+0)&""
A11: 1 | B11: B02 | C11: ITS5-ITS4 | D11: =OFFSET(plates!$B$4,CODE(LEFT(B11,1))-64,-1)&"-"&OFFSET(plates!$B$4,-1,MID(B11,2,3)+0) -> bc060-bc062 | E11: =OFFSET(plates!$B$4,CODE(LEFT(B11,1))-64,MID(B11,2,3)+0)&""
A12: 1 | B12: C02 | C12: ITS5-ITS4 | D12: =OFFSET(plates!$B$4,CODE(LEFT(B12,1))-64,-1)&"-"&OFFSET(plates!$B$4,-1,MID(B12,2,3)+0) -> bc061-bc062 | E12: =OFFSET(plates!$B$4,CODE(LEFT(B12,1))-64,MID(B12,2,3)+0)&""
A13: 1 | B13: D02 | C13: ITS5-ITS4 | D13: =OFFSET(plates!$B$4,CODE(LEFT(B13,1))-64,-1)&"-"&OFFSET(plates!$B$4,-1,MID(B13,2,3)+0) -> bc062-bc062 | E13: =OFFSET(plates!$B$4,CODE(LEFT(B13,1))-64,MID(B13,2,3)+0)&""
... A97: 1 | B97: H12 | C97: ITS5-ITS4 | D97: =OFFSET(plates!$B$4,CODE(LEFT(B97,1))-64,-1)&"-"&OFFSET(plates!$B$4,-1,MID(B97,2,3)+0) -> bc157-bc245 | E97: =OFFSET(plates!$B$4,CODE(LEFT(B97,1))-64,MID(B97,2,3)+0)&""
A98: 2 | B98: A01 | C98: ITS5-ITS4 | D98: =OFFSET(plates!$B$14,CODE(LEFT(B98,1))-64,-1)&"-"&OFFSET(plates!$B$4,-1,MID(B98,2,3)+0) -> bc168-bc019 | E98: =OFFSET(plates!$B$14,CODE(LEFT(B98,1))-64,MID(B98,2,3)+0)&""
A99: 2 | B99: B01 | C99: ITS5-ITS4 | D99: =OFFSET(plates!$B$14,CODE(LEFT(B99,1))-64,-1)&"-"&OFFSET(plates!$B$4,-1,MID(B99,2,3)+0) -> bc183-bc019 | E99: =OFFSET(plates!$B$14,CODE(LEFT(B99,1))-64,MID(B99,2,3)+0)&""
A100: 2 | B100: C01 | C100: ITS5-ITS4 | D100: =OFFSET(plates!$B$14,CODE(LEFT(B100,1))-64,-1)&"-"&OFFSET(plates!$B$4,-1,MID(B100,2,3)+0) -> bc192-bc019 | E100: =OFFSET(plates!$B$14,CODE(LEFT(B100,1))-64,MID(B100,2,3)+0)&""
A101: 2 | B101: D01 | C101: ITS5-ITS4 | D101: =OFFSET(plates!$B$14,CODE(LEFT(B101,1))-64,-1)&"-"&OFFSET(plates!$B$4,-1,MID(B101,2,3)+0) -> bc205-bc019 | E101: =OFFSET(plates!$B$14,CODE(LEFT(B101,1))-64,MID(B101,2,3)+0)&""
A102: 2 | B102: E01 | C102: ITS5-ITS4 | D102: =OFFSET(plates!$B$14,CODE(LEFT(B102,1))-64,-1)&"-"&OFFSET(plates!$B$4,-1,MID(B102,2,3)+0) -> bc219-bc019 | E102: =OFFSET(plates!$B$14,CODE(LEFT(B102,1))-64,MID(B102,2,3)+0)&""
A103: 2 | B103: F01 | C103: ITS5-ITS4 | D103: =OFFSET(plates!$B$14,CODE(LEFT(B103,1))-64,-1)&"-"&OFFSET(plates!$B$4,-1,MID(B103,2,3)+0) -> bc220-bc019 | E103: =OFFSET(plates!$B$14,CODE(LEFT(B103,1))-64,MID(B103,2,3)+0)&""
A104: 2 | B104: G01 | C104: ITS5-ITS4 | D104: =OFFSET(plates!$B$14,CODE(LEFT(B104,1))-64,-1)&"-"&OFFSET(plates!$B$4,-1,MID(B104,2,3)+0) -> bc258-bc019 | E104: =OFFSET(plates!$B$14,CODE(LEFT(B104,1))-64,MID(B104,2,3)+0)&""
A105: 2 | B105: H01 | C105: ITS5-ITS4 | D105: =OFFSET(plates!$B$14,CODE(LEFT(B105,1))-64,-1)&"-"&OFFSET(plates!$B$4,-1,MID(B105,2,3)+0) -> bc264-bc019 | E105: =OFFSET(plates!$B$14,CODE(LEFT(B105,1))-64,MID(B105,2,3)+0)&""
A106: 2 | B106: A02 | C106: ITS5-ITS4 | D106: =OFFSET(plates!$B$14,CODE(LEFT(B106,1))-64,-1)&"-"&OFFSET(plates!$B$4,-1,MID(B106,2,3)+0) -> bc168-bc062 | E106: =OFFSET(plates!$B$14,CODE(LEFT(B106,1))-64,MID(B106,2,3)+0)&""
A107: 2 | B107: B02 | C107: ITS5-ITS4 | D107: =OFFSET(plates!$B$14,CODE(LEFT(B107,1))-64,-1)&"-"&OFFSET(plates!$B$4,-1,MID(B107,2,3)+0) -> bc183-bc062 | E107: =OFFSET(plates!$B$14,CODE(LEFT(B107,1))-64,MID(B107,2,3)+0)&""
A108: 2 | B108: C02 | C108: ITS5-ITS4 | D108: =OFFSET(plates!$B$14,CODE(LEFT(B108,1))-64,-1)&"-"&OFFSET(plates!$B$4,-1,MID(B108,2,3)+0) -> bc192-bc062 | E108: =OFFSET(plates!$B$14,CODE(LEFT(B108,1))-64,MID(B108,2,3)+0)&""
A109: 2 | B109: D02 | C109: ITS5-ITS4 | D109: =OFFSET(plates!$B$14,CODE(LEFT(B109,1))-64,-1)&"-"&OFFSET(plates!$B$4,-1,MID(B109,2,3)+0) -> bc205-bc062 | E109: =OFFSET(plates!$B$14,CODE(LEFT(B109,1))-64,MID(B109,2,3)+0)&""
... A193: 2 | B193: H12 | C193: ITS5-ITS4 | D193: =OFFSET(plates!$B$14,CODE(LEFT(B193,1))-64,-1)&"-"&OFFSET(plates!$B$4,-1,MID(B193,2,3)+0) -> bc264-bc245 | E193: =OFFSET(plates!$B$14,CODE(LEFT(B193,1))-64,MID(B193,2,3)+0)&""
A194: 3 | B194: A01 | C194: ITS5-ITS4 | D194: =OFFSET(plates!$B$24,CODE(LEFT(B194,1))-64,-1)&"-"&OFFSET(plates!$B$4,-1,MID(B194,2,3)+0) -> bc272-bc019 | E194: =OFFSET(plates!$B$24,CODE(LEFT(B194,1))-64,MID(B194,2,3)+0)&""
A195: 3 | B195: B01 | C195: ITS5-ITS4 | D195: =OFFSET(plates!$B$24,CODE(LEFT(B195,1))-64,-1)&"-"&OFFSET(plates!$B$4,-1,MID(B195,2,3)+0) -> bc277-bc019 | E195: =OFFSET(plates!$B$24,CODE(LEFT(B195,1))-64,MID(B195,2,3)+0)&""
A196: 3 | B196: C01 | C196: ITS5-ITS4 | D196: =OFFSET(plates!$B$24,CODE(LEFT(B196,1))-64,-1)&"-"&OFFSET(plates!$B$4,-1,MID(B196,2,3)+0) -> bc282-bc019 | E196: =OFFSET(plates!$B$24,CODE(LEFT(B196,1))-64,MID(B196,2,3)+0)&""
A197: 3 | B197: D01 | C197: ITS5-ITS4 | D197: =OFFSET(plates!$B$24,CODE(LEFT(B197,1))-64,-1)&"-"&OFFSET(plates!$B$4,-1,MID(B197,2,3)+0) -> bc286-bc019 | E197: =OFFSET(plates!$B$24,CODE(LEFT(B197,1))-64,MID(B197,2,3)+0)&""
A198: 3 | B198: E01 | C198: ITS5-ITS4 | D198: =OFFSET(plates!$B$24,CODE(LEFT(B198,1))-64,-1)&"-"&OFFSET(plates!$B$4,-1,MID(B198,2,3)+0) -> bc298-bc019 | E198: =OFFSET(plates!$B$24,CODE(LEFT(B198,1))-64,MID(B198,2,3)+0)&""
A199: 3 | B199: F01 | C199: ITS5-ITS4 | D199: =OFFSET(plates!$B$24,CODE(LEFT(B199,1))-64,-1)&"-"&OFFSET(plates!$B$4,-1,MID(B199,2,3)+0) -> bc314-bc019 | E199: =OFFSET(plates!$B$24,CODE(LEFT(B199,1))-64,MID(B199,2,3)+0)&""
A200: 3 | B200: G01 | C200: ITS5-ITS4 | D200: =OFFSET(plates!$B$24,CODE(LEFT(B200,1))-64,-1)&"-"&OFFSET(plates!$B$4,-1,MID(B200,2,3)+0) -> bc321-bc019 | E200: =OFFSET(plates!$B$24,CODE(LEFT(B200,1))-64,MID(B200,2,3)+0)&""
A201: 3 | B201: H01 | C201: ITS5-ITS4 | D201: =OFFSET(plates!$B$24,CODE(LEFT(B201,1))-64,-1)&"-"&OFFSET(plates!$B$4,-1,MID(B201,2,3)+0) -> bc324-bc019 | E201: =OFFSET(plates!$B$24,CODE(LEFT(B201,1))-64,MID(B201,2,3)+0)&""
A202: 3 | B202: A02 | C202: ITS5-ITS4 | D202: =OFFSET(plates!$B$24,CODE(LEFT(B202,1))-64,-1)&"-"&OFFSET(plates!$B$4,-1,MID(B202,2,3)+0) -> bc272-bc062 | E202: =OFFSET(plates!$B$24,CODE(LEFT(B202,1))-64,MID(B202,2,3)+0)&""
A203: 3 | B203: B02 | C203: ITS5-ITS4 | D203: =OFFSET(plates!$B$24,CODE(LEFT(B203,1))-64,-1)&"-"&OFFSET(plates!$B$4,-1,MID(B203,2,3)+0) -> bc277-bc062 | E203: =OFFSET(plates!$B$24,CODE(LEFT(B203,1))-64,MID(B203,2,3)+0)&""
A204: 3 | B204: C02 | C204: ITS5-ITS4 | D204: =OFFSET(plates!$B$24,CODE(LEFT(B204,1))-64,-1)&"-"&OFFSET(plates!$B$4,-1,MID(B204,2,3)+0) -> bc282-bc062 | E204: =OFFSET(plates!$B$24,CODE(LEFT(B204,1))-64,MID(B204,2,3)+0)&""
A205: 3 | B205: D02 | C205: ITS5-ITS4 | D205: =OFFSET(plates!$B$24,CODE(LEFT(B205,1))-64,-1)&"-"&OFFSET(plates!$B$4,-1,MID(B205,2,3)+0) -> bc286-bc062 | E205: =OFFSET(plates!$B$24,CODE(LEFT(B205,1))-64,MID(B205,2,3)+0)&""
... A289: 3 | B289: H12 | C289: ITS5-ITS4 | D289: =OFFSET(plates!$B$24,CODE(LEFT(B289,1))-64,-1)&"-"&OFFSET(plates!$B$4,-1,MID(B289,2,3)+0) -> bc324-bc245 | E289: =OFFSET(plates!$B$24,CODE(LEFT(B289,1))-64,MID(B289,2,3)+0)&""
...

Sheet primers
A1: primer-index | B1: index_seq | C1: primer_seq
A2: ITS5-bc018 | B2: AACGTCACT | C2: GGAAGTAAAAGTCGTAACAAGG
A3: ITS5-bc060 | B3: ACACTCTAG | C3: GGAAGTAAAAGTCGTAACAAGG
A4: ITS5-bc061 | B4: ACAGATGAG | C4: GGAAGTAAAAGTCGTAACAAGG
A5: ITS5-bc062 | B5: ACAGTCCTT | C5: GGAAGTAAAAGTCGTAACAAGG
A6: ITS5-bc095 | B6: ACTCCACAT | C6: GGAAGTAAAAGTCGTAACAAGG
A7: ITS5-bc139 | B7: AGTCGCTAT | C7: GGAAGTAAAAGTCGTAACAAGG
A8: ITS5-bc148 | B8: ATACCGTCG | C8: GGAAGTAAAAGTCGTAACAAGG
A9: ITS5-bc157 | B9: ATCGCAGAG | C9: GGAAGTAAAAGTCGTAACAAGG
A10: ITS5-bc168 | B10: ATGTGCAAG | C10: GGAAGTAAAAGTCGTAACAAGG
A11: ITS5-bc183 | B11: CAAGTCTGG | C11: GGAAGTAAAAGTCGTAACAAGG
A12: ITS5-bc192 | B12: CACCGATTG | C12: GGAAGTAAAAGTCGTAACAAGG
... A77: ITS4-bc538 | B77: TTAAGGTGG | C77: TCCTCCGCTTATTGATATGC
